Workbook

Sheet Read Me
A1: Stairs Benchmark SB-1: Independent ACI 318-19 Hand Calculation vs Ñola Stairs Module
A3: Purpose | B3: Independent check of the Stairs module (engine stairs-0.1.0) on the MDM stair geometry with corrected design basis.
A4: Code | B4: ACI 318-19 (NSCP 2015 recorded as project standard). Combinations 1.2D + 1.6L and 1.4D.
A5: Structure | B5: Dog-leg, 2 × 13 risers, R 153.85, T 340, waist and landing 200 mm, B 1.8 m, mid landing 1,460 mm.
A6: Supports | B6: Flight 1: footing on soil (pinned) to landing beam (pinned). Flight 2: landing beam (pinned) to floor beam (fixed).
A7: Method | B7: Frame by force method / virtual work (hand.py, written separately from the module's stiffness solver); section checks as live Excel formulas from the ACI clauses; module values pasted from analyzeStairs().
A8: Colour code | B8: Blue = input · Black = Excel formula · Green = link to another sheet · Purple = value from hand.py or module output.
A9: Not independent | B9: Both use the same plan-load convention (steps to the last riser line) and the same thrust-envelope assumption; Findings 2 and 6 cover these.
A10: Result
A11: Values compared | B11: =Comparison!D58 -> 46
A12: MATCH | B12: =Comparison!D59 -> 46
A13: FLAG | B13: =Comparison!D60 -> 0
A14: Largest |Δ| | B14: =Comparison!D61 -> 0.0015467606
A15: Sign-off | B15: Engineer: ____________________ Date: __________ (review the Findings sheet first)

Sheet Inputs
A1: SB-1 Inputs (blue = input)
A3: Item | B3: Symbol | C3: Value | D3: Unit | E3: Reference / formula | F3: Note
A5: Materials
A6: Concrete strength | B6: f'c | C6: 27.6 | D6: MPa | E6: User
A7: Rebar yield strength | B7: fy | C7: 414 | D7: MPa | E7: User (Grade 60 / PNS 49 Gr 415)
A8: Rebar modulus | B8: Es | C8: 200000 | D8: MPa | E8: ACI 318-19 20.2.2.2
A9: Concrete unit weight | B9: γc | C9: 24 | D9: kN/m³ | E9: Module default
A11: Geometry
A12: Floor to floor | B12: H | C12: 4000 | D12: mm | E12: MDM sheet
A13: Risers per flight | B13: n | C13: 13 | E13: MDM sheet (2 × 13)
A14: Riser | B14: R | C14: =Inputs!$C$12/(2*Inputs!$C$13) -> 153.84615 | D14: mm | E14: H / (2n) = 153.85
A15: Going (tread) | B15: T | C15: 340 | D15: mm | E15: MDM sheet
A16: Waist thickness (normal to soffit) | B16: t | C16: 200 | D16: mm | E16: Assumed: MDM's 100 mm fails hmin
A17: Landing thickness | B17: tl | C17: 200 | D17: mm | E17: Assumed
A18: Mid-landing length (along run) | B18: Ll | C18: 1460 | D18: mm | E18: MDM sheet
A19: Flight width | B19: B | C19: 1800 | D19: mm | E19: MDM sheet
A20: Clear cover (top and bottom) | B20: cc | C20: 20 | D20: mm | E20: Agreed default
A21: Support bearing width (all beams) | B21: b | C21: 250 | D21: mm | E21: Agreed default (250 × 500 beams)
A23: Loads and combinations
A24: Finishes on plan | B24: SDL | C24: 1 | D24: kPa | E24: Agreed default
A25: Live load | B25: L | C25: 4.8 | D25: kPa | E25: NSCP 2015 Table 205-1 / ASCE 7 (stairs)
A26: LC1 dead factor | C26: 1.2 | E26: ACI 318-19 Table 5.3.1 (5.3.1b)
A27: LC1 live factor | C27: 1.6 | E27: ACI 318-19 Table 5.3.1 (5.3.1b)
A28: LC2 dead factor | C28: 1.4 | E28: ACI 318-19 Table 5.3.1 (5.3.1a)
A30: Reinforcement (module defaults)
A31: B1 main bottom: bar | B31: db | C31: 12 | D31: mm
A32: B1 main bottom: spacing | B32: s | C32: 150 | D32: mm
A33: T1 top at bottom support: bar | B33: db | C33: 12 | D33: mm
A34: T1 top at bottom support: spacing | B34: s | C34: 300 | D34: mm
A35: T2 top at top support: bar | B35: db | C35: 12 | D35: mm
A36: T2 top at top support: spacing | B36: s | C36: 300 | D36: mm
A37: T3 top at knees / landing: bar | B37: db | C37: 12 | D37: mm
A38: T3 top at knees / landing: spacing | B38: s | C38: 200 | D38: mm
A39: D1 distribution: bar | B39: db | C39: 10 | D39: mm
A40: D1 distribution: spacing | B40: s | C40: 200 | D40: mm
A41: Bottom-bar extension past knee | C41: 600 | D41: mm | E41: Module default
A42: T3 top-bar extension each side of knee | C42: 700 | D42: mm | E42: Module default
A44: Supports and footing
A45: Bottom of flight 1 | C45: Footing on soil, pinned | E45: User
A46: Mid landing far edge | C46: Landing beam, pinned | E46: User
...

Sheet Loads
A1: Loads on Plan (per 1 m strip)
A3: Item | B3: Symbol | C3: Value | D3: Unit | E3: Reference / formula | F3: Note
A5: Pitch
A6: Pitch angle | B6: θ | C6: =DEGREES(ATAN(Inputs!$C$14/Inputs!$C$15)) -> 24.346214 | D6: deg | E6: atan(R/T)
A7: cos θ | C7: =COS(RADIANS(Loads!$C$6)) -> 0.91107106
A8: tan θ | C8: =Inputs!$C$14/Inputs!$C$15 -> 0.45248869
A10: Dead load
A11: Waist γc·t/cosθ | C11: =Inputs!$C$9*Inputs!$C$16/1000/Loads!$C$7 -> 5.2685243 | D11: kPa | E11: Slab on slope converted to plan
A12: Steps γc·R/2 | C12: =Inputs!$C$9*Inputs!$C$14/1000/2 -> 1.8461538 | D12: kPa | E12: Triangular steps, average depth R/2
A13: Flight dead load | B13: wD,f | C13: =Loads!$C$11+Loads!$C$12+Inputs!$C$24 -> 8.1146781 | D13: kPa | E13: Waist + steps + finishes
A14: Landing dead load | B14: wD,l | C14: =Inputs!$C$9*Inputs!$C$17/1000+Inputs!$C$24 -> 5.8 | D14: kPa
A16: Factored (governing LC1)
A17: Flight wu | C17: =Inputs!$C$26*Loads!$C$13+Inputs!$C$27*Inputs!$C$25 -> 17.417614 | D17: kPa | E17: 1.2D + 1.6L
A18: Landing wu | C18: =Inputs!$C$26*Loads!$C$14+Inputs!$C$27*Inputs!$C$25 -> 14.64 | D18: kPa | E18: 1.2D + 1.6L
A20: Plan load regions (convention)
A21: Flight 1: steps end at last riser line (n−1)T | C21: =(Inputs!$C$13-1)*Inputs!$C$15 -> 4080 | D21: mm | E21: Landing top is the last tread
A22: Flight 1 strip span on plan | B22: L1 | C22: =Loads!$C$21+Inputs!$C$18 -> 5540 | D22: mm | E22: Bottom pin to landing beam
A23: Flight 2 strip span on plan | B23: L2 | C23: =Inputs!$C$18+Inputs!$C$13*Inputs!$C$15 -> 5880 | D23: mm | E23: Landing beam to top beam

Sheet Frame
A1: Frame Analysis: Force Method (Virtual Work), Independent of the Module Solver
A3: Item | B3: Symbol | C3: Value | D3: Unit | E3: Reference / formula | F3: Note
A5: Method
A6: Model | C6: Centreline frame | E6: Waist line parallel to pitch line at t/(2cosθ) below it; landing at tl/2 below its top; knee at the intersection
A7: Solution | C7: Force method | E7: Primary structure pin + roller; redundants by δ10 + Σ Xj δ1j = 0, δ = ∫M m/EI ds + ∫N n/EA ds (gross EcIg, Ec = 4700√f'c), 3,000 segments per member | F7: Script hand.py (purple values)
A8: Thrust envelope | C8: Both cases | E8: Horizontal restraint at both supports (restrained) and released at the second support (released); results enveloped, as in the module
A10: Excel closed-form check: flight 1 strip, horizontal restraint released (simply supported on plan)
A11: Left reaction under LC1 | B11: RA | C11: =(Loads!$C$17*Loads!$C$21/1000*(Loads!$C$22-Loads!$C$21/2)/1000+Loads!$C$18*Inputs!$C$18/1000*(Inputs!$C$18/2)/1000)/(Loads!$C$22/1000) -> 47.712425 | D11: kN/m | E11: Moments about the landing beam
A12: Zero shear from left | B12: x0 | C12: =Frame!$C$11/Loads!$C$17 -> 2.7393204 | D12: m | E12: Within flight (x0 < xe1)
A13: Mu+ max (released case) | B13: Mu+ | C13: =Frame!$C$11*Frame!$C$12/2 -> 65.349811 | D13: kN·m/m | E13: RA·x0/2
A14: Knee x (flight 1) | C14: =Inputs!$C$13*Inputs!$C$15+(Inputs!$C$16/(2*Loads!$C$7)-Inputs!$C$17/2)/Loads!$C$8 -> 4441.5716 | D14: mm | E14: Centreline intersection
A16: Flight 1 strip (pinned footing, pinned landing beam)
A17: Footing: dead vertical (service) | C17: 51.241684 | D17: kN/m | E17: Restrained case (larger)
A18: Footing: live vertical (service) | C18: 31.580887 | D18: kN/m
A19: Footing: service thrust H (restrained) | C19: 130.91948 | D19: kN/m | E19: D + L
A20: Footing: factored V max | C20: 112.01944 | D20: kN/m | E20: Envelope
A21: Footing: factored |H| max | C21: 177.26464 | D21: kN/m
A22: Landing beam: dead vertical | C22: 19.544084 | D22: kN/m | E22: Released case (larger)
A23: Landing beam: live vertical | C23: 13.296 | D23: kN/m
A24: Landing beam: factored V min (uplift if < 0) | C24: -19.580276 | D24: kN/m | E24: Restrained case, LC2/LC1
A25: Mu+ max, waist | C25: 65.350464 | D25: kN·m/m | E25: at x = 2.74 m (released case)
A26: Mu+ max, landing | C26: 40.291705 | D26: kN·m/m | E26: at the knee
A27: Mu− max, knee | C27: -30.33291 | D27: kN·m/m | E27: Restrained case (thrust)
A28: Vu max outside support zones (b/2 + d) | C28: 40.567536 | D28: kN/m | E28: at x = 4.44 m (knee)
A29: Max axial tension | C29: 11.800157 | D29: kN/m
A31: Flight 2 strip (pinned landing beam, fixed top beam)
A32: Landing beam: dead vertical | C32: 15.153923 | D32: kN/m | E32: Released case (larger)
A33: Top beam: dead vertical | C33: 45.427496 | D33: kN/m | E33: Restrained case (larger)
A34: Top beam: live vertical | C34: 27.882941 | D34: kN/m
A35: Top beam: factored fixed-end |M| | C35: 73.56358 | D35: kN·m/m | E35: Released case governs (1.2·33.77 + 1.6·20.68)
A36: Mu+ max, landing | C36: 35.987066 | D36: kN·m/m | E36: at the knee
A37: Mu+ max, waist | C37: 41.134934 | D37: kN·m/m | E37: at x = 2.25 m
A38: Mu− at knee (landing side) | C38: -17.196311 | D38: kN·m/m
A39: Vu max outside support zones | C39: 52.831277 | D39: kN/m | E39: at x = 5.58 m (b/2 + d from top beam)
A40: Max axial tension (at top beam) | C40: 155.46308 | D40: kN/m | E40: Released case

Sheet Sections
A1: Section Capacities and Detailing (ACI 318-19)
A3: Item | B3: Symbol | C3: Value | D3: Unit | E3: Reference / formula | F3: Note
A4: Effective depth, 12 mm bars | B4: d | C4: =Inputs!$C$16-Inputs!$C$20-Inputs!$C$31/2 -> 174 | D4: mm | E4: h − cc − db/2
A5: β1 | C5: =IF(Inputs!$C$6<=28,0.85,MAX(0.65,0.85-0.05*(Inputs!$C$6-28)/7)) -> 0.85 | E5: Table 22.2.2.4.3
A7: B1: Ø12 flexure (Whitney block)
A8: As per metre | B8: As | C8: =PI()*Inputs!$C$31^2/4*1000/Inputs!$C$32 -> 753.98224 | D8: mm²/m
A9: Block depth | B9: a | C9: =Sections!$C$8*Inputs!$C$7/(0.85*Inputs!$C$6*1000) -> 13.305569 | D9: mm | E9: 22.2.2.4.1
A10: Steel strain | B10: εt | C10: =0.003*(Sections!$C$4-Sections!$C$9/Sections!$C$5)/(Sections!$C$9/Sections!$C$5) -> 0.030346939 | E10: 22.2.1.2
A11: φ | C11: =0.65+0.25*MIN(1,MAX(0,(Sections!$C$10-Inputs!$C$7/Inputs!$C$8)/0.003)) -> 0.9 | E11: Table 21.2.2
A12: φMn | C12: =Sections!$C$11*Sections!$C$8*Inputs!$C$7*(Sections!$C$4-Sections!$C$9/2)/1000000 -> 47.013486 | D12: kN·m/m | E12: 22.2
A14: T1: Ø12 flexure (Whitney block)
A15: As per metre | B15: As | C15: =PI()*Inputs!$C$33^2/4*1000/Inputs!$C$34 -> 376.99112 | D15: mm²/m
A16: Block depth | B16: a | C16: =Sections!$C$15*Inputs!$C$7/(0.85*Inputs!$C$6*1000) -> 6.6527844 | D16: mm | E16: 22.2.2.4.1
A17: Steel strain | B17: εt | C17: =0.003*(Sections!$C$4-Sections!$C$16/Sections!$C$5)/(Sections!$C$16/Sections!$C$5) -> 0.063693879 | E17: 22.2.1.2
A18: φ | C18: =0.65+0.25*MIN(1,MAX(0,(Sections!$C$17-Inputs!$C$7/Inputs!$C$8)/0.003)) -> 0.9 | E18: Table 21.2.2
A19: φMn | C19: =Sections!$C$18*Sections!$C$15*Inputs!$C$7*(Sections!$C$4-Sections!$C$16/2)/1000000 -> 23.973991 | D19: kN·m/m | E19: 22.2
A21: T2: Ø12 flexure (Whitney block)
A22: As per metre | B22: As | C22: =PI()*Inputs!$C$35^2/4*1000/Inputs!$C$36 -> 376.99112 | D22: mm²/m
A23: Block depth | B23: a | C23: =Sections!$C$22*Inputs!$C$7/(0.85*Inputs!$C$6*1000) -> 6.6527844 | D23: mm | E23: 22.2.2.4.1
A24: Steel strain | B24: εt | C24: =0.003*(Sections!$C$4-Sections!$C$23/Sections!$C$5)/(Sections!$C$23/Sections!$C$5) -> 0.063693879 | E24: 22.2.1.2
A25: φ | C25: =0.65+0.25*MIN(1,MAX(0,(Sections!$C$24-Inputs!$C$7/Inputs!$C$8)/0.003)) -> 0.9 | E25: Table 21.2.2
A26: φMn | C26: =Sections!$C$25*Sections!$C$22*Inputs!$C$7*(Sections!$C$4-Sections!$C$23/2)/1000000 -> 23.973991 | D26: kN·m/m | E26: 22.2
A28: T3: Ø12 flexure (Whitney block)
A29: As per metre | B29: As | C29: =PI()*Inputs!$C$37^2/4*1000/Inputs!$C$38 -> 565.48668 | D29: mm²/m
A30: Block depth | B30: a | C30: =Sections!$C$29*Inputs!$C$7/(0.85*Inputs!$C$6*1000) -> 9.9791767 | D30: mm | E30: 22.2.2.4.1
A31: Steel strain | B31: εt | C31: =0.003*(Sections!$C$4-Sections!$C$30/Sections!$C$5)/(Sections!$C$30/Sections!$C$5) -> 0.041462586 | E31: 22.2.1.2
A32: φ | C32: =0.65+0.25*MIN(1,MAX(0,(Sections!$C$31-Inputs!$C$7/Inputs!$C$8)/0.003)) -> 0.9 | E32: Table 21.2.2
A33: φMn | C33: =Sections!$C$32*Sections!$C$29*Inputs!$C$7*(Sections!$C$4-Sections!$C$30/2)/1000000 -> 35.610551 | D33: kN·m/m | E33: 22.2
A35: One-way shear, Table 22.5.5.1(c)
A36: Size effect λs | C36: =MIN(1,SQRT(2/(1+0.004*Sections!$C$4))) -> 1 | E36: 22.5.5.1.3
A37: √f'c (≤ 8.3) | C37: =MIN(SQRT(Inputs!$C$6),8.3) -> 5.2535702 | D37: MPa | E37: 22.5.3.1
A38: φVc with B1 (ρw from bottom bars), Nu = 0 | C38: =0.75*0.66*Sections!$C$36*(Sections!$C$8/(1000*Sections!$C$4))^(1/3)*Sections!$C$37*Sections!$C$4 -> 73.769971 | D38: kN/m | E38: φ = 0.75
A39: φVc with T3, Nu = 0 | C39: =0.75*0.66*Sections!$C$36*(Sections!$C$29/(1000*Sections!$C$4))^(1/3)*Sections!$C$37*Sections!$C$4 -> 67.024466 | D39: kN/m | E39: Knee hogging zone
A40: φVc with T2, Nu = tension at top beam | C40: =0.75*MAX(0,0.66*Sections!$C$36*(Sections!$C$22/(1000*Sections!$C$4))^(1/3)*Sections!$C$37-Frame!$C$40*1000/(6*1000*Inputs!$C$16))*Sections!$C$4 -> 41.644655 | D40: kN/m | E40: Nu/(6Ag) term with tension (conservative: max Nu)
A42: Minimum steel, spacing, crack control
A43: ρ min (fy < 420 → 0.0020) | C43: =IF(Inputs!$C$7<420,0.002,MAX(0.0018*420/Inputs!$C$7,0.0014)) -> 0.002 | E43: Table 24.4.3.2 / 7.6.1.1
A44: As,min = ρmin·b·h | C44: =Sections!$C$43*1000*Inputs!$C$16 -> 400 | D44: mm²/m
A45: s max, main bars | C45: =MIN(3*Inputs!$C$16,450) -> 450 | D45: mm | E45: 7.7.2.3
A46: fs = 2/3 fy | C46: =2/3*Inputs!$C$7 -> 276 | D46: MPa | E46: 24.3.2.1
A47: Crack-control spacing | C47: =MIN(380*280/Sections!$C$46-2.5*Inputs!$C$20,300*280/Sections!$C$46) -> 304.34783 | D47: mm | E47: Table 24.3.2
...

Sheet Serviceability
A1: Minimum Thickness and Deflection
A3: Item | B3: Symbol | C3: Value | D3: Unit | E3: Reference / formula | F3: Note
A5: Minimum thickness, Table 7.3.1.1 on developed length
A6: fy factor 0.4 + fy/700 | C6: =0.4+Inputs!$C$7/700 -> 0.99142857 | E6: 7.3.1.1.1
A7: Flight 1 strip developed length | C7: 5973.5384 | D7: mm | E7: Centreline, from Frame model
A8: hmin flight 1 (simply supported, ℓ/20) | C8: =Serviceability!$C$7/20*Serviceability!$C$6 -> 296.11683 | D8: mm
A9: Flight 2 strip developed length | C9: 6309.3272 | D9: mm
A10: hmin flight 2 (one end continuous, ℓ/24) | C10: =Serviceability!$C$9/24*Serviceability!$C$6 -> 260.6353 | D10: mm | E10: Fixed top
A12: Effective inertia, Table 24.2.3.5 (B1 bottom bars, governing sagging)
A13: Ec = 4700√f'c | C13: =4700*SQRT(Inputs!$C$6) -> 24691.78 | D13: MPa | E13: 19.2.2.1(b)
A14: n = Es/Ec | C14: =Inputs!$C$8/Serviceability!$C$13 -> 8.0998616
A15: Ig per metre | C15: =1000*Inputs!$C$16^3/12 -> 6.6666667e+08 | D15: mm⁴
A16: Cracked neutral axis | C16: =(-Serviceability!$C$14*Sections!$C$8+SQRT((Serviceability!$C$14*Sections!$C$8)^2+2*1000*Serviceability!$C$14*Sections!$C$8*Sections!$C$4))/1000 -> 40.396462 | D16: mm
A17: Icr | C17: =1000*Serviceability!$C$16^3/3+Serviceability!$C$14*Sections!$C$8*(Sections!$C$4-Serviceability!$C$16)^2 -> 1.3098606e+08 | D17: mm⁴
A18: Mcr = fr Ig / yt | C18: =0.62*SQRT(Inputs!$C$6)*Serviceability!$C$15/(Inputs!$C$16/2)/1000000 -> 21.714757 | D18: kN·m/m | E18: 19.2.3.1
A19: Ma flight 1 strip (max service D+L) | C19: 48.321245 | D19: kN·m/m | E19: From Frame model
A20: Ie/Ig flight 1 strip | C20: =MIN(Serviceability!$C$15,Serviceability!$C$17/(1-(2/3*Serviceability!$C$18/Serviceability!$C$19)^2*(1-Serviceability!$C$17/Serviceability!$C$15)))/Serviceability!$C$15 -> 0.21175026 | E20: Ie applied to the whole span
A21: Ma flight 2 strip (max service D+L) | C21: 30.382649 | D21: kN·m/m | E21: From Frame model
A22: Ie/Ig flight 2 strip | C22: =MIN(Serviceability!$C$15,Serviceability!$C$17/(1-(2/3*Serviceability!$C$18/Serviceability!$C$21)^2*(1-Serviceability!$C$17/Serviceability!$C$15)))/Serviceability!$C$15 -> 0.24031799 | E22: Ie applied to the whole span
A24: Deflection by virtual work with EcIe (envelope of both thrust cases)
A25: Flight 1: immediate live ΔL | C25: 18.469269 | D25: mm | E25: Unit load scanned at 111 points
A26: Flight 1: long-term λΔ·ΔD + ΔL (λΔ = 2.0, ψ = 0) | C26: 78.099379 | D26: mm | E26: 24.2.4.1
A27: Flight 1: limit ℓ/360 | C27: =Loads!$C$22/360 -> 15.388889 | D27: mm | E27: Table 24.2.2
A28: Flight 1: limit ℓ/240 | C28: =Loads!$C$22/240 -> 23.083333 | D28: mm | E28: Table 24.2.2
A29: Flight 2: immediate live ΔL | C29: 8.5367113 | D29: mm | E29: Unit load scanned at 111 points
A30: Flight 2: long-term λΔ·ΔD + ΔL (λΔ = 2.0, ψ = 0) | C30: 35.871666 | D30: mm | E30: 24.2.4.1
A31: Flight 2: limit ℓ/360 | C31: =Loads!$C$23/360 -> 16.333333 | D31: mm | E31: Table 24.2.2
A32: Flight 2: limit ℓ/240 | C32: =Loads!$C$23/240 -> 24.5 | D32: mm | E32: Table 24.2.2

Sheet Footing
A1: Footing Under the Bottom Support (Strip Footing per m)
A3: Item | B3: Symbol | C3: Value | D3: Unit | E3: Reference / formula | F3: Note
A4: Stair service reaction D + L | C4: =Frame!$C$17+Frame!$C$18 -> 82.82257 | D4: kN/m | E4: Frame (restrained case)
A5: Footing weight | C5: =Inputs!$C$9*Inputs!$C$49/1000*Inputs!$C$50/1000 -> 4.32 | D5: kN/m
A6: Soil on footing (outside the seat) | C6: =Inputs!$C$52*Inputs!$C$51/1000*(Inputs!$C$49-Inputs!$C$21)/1000 -> 4.41 | D6: kN/m
A7: Total P | C7: =Footing!$C$4+Footing!$C$5+Footing!$C$6 -> 91.55257 | D7: kN/m
A8: Eccentricity e = H·hf / P | C8: =ABS(Frame!$C$19)*Inputs!$C$50/1000/Footing!$C$7 -> 0.42899773 | D8: m | E8: Pinned seat, M = 0
A9: Kern limit Bf/6 | C9: =Inputs!$C$49/1000/6 -> 0.1 | D9: m
A10: q max (∞ if e ≥ Bf/2) | C10: =IF(Footing!$C$8<=Footing!$C$9,Footing!$C$7/(Inputs!$C$49/1000)*(1+6*Footing!$C$8/(Inputs!$C$49/1000)),IF(Footing!$C$8<Inputs!$C$49/2000,2*Footing!$C$7/(3*(Inputs!$C$49/2000-Footing!$C$8)),"Outside")) -> Outside | D10: kPa | E10: Resultant outside the footing
A11: Sliding μP/H | C11: =Inputs!$C$53*Footing!$C$7/ABS(Frame!$C$19) -> 0.31468698 | E11: Required 1.5
A12: Footing d | C12: =Inputs!$C$50-Inputs!$C$54-Inputs!$C$55/2 -> 219 | D12: mm
A13: Footing φMn (Ø12 @ 200) | C13: =0.9*(PI()*Inputs!$C$55^2/4*1000/Inputs!$C$56)*Inputs!$C$7*(Footing!$C$12-(PI()*Inputs!$C$55^2/4*1000/Inputs!$C$56)*Inputs!$C$7/(0.85*Inputs!$C$6*1000)/2)/1000000 -> 45.092066 | D13: kN·m/m | E13: Tension-controlled (εt large)
A14: As,min = ρmin·b·hf | C14: =Sections!$C$43*1000*Inputs!$C$50 -> 600 | D14: mm²/m
A15: As provided | C15: =PI()*Inputs!$C$55^2/4*1000/Inputs!$C$56 -> 565.48668 | D15: mm²/m
A16: Hook space available hf − cover − Ø | C16: =Inputs!$C$50-Inputs!$C$54-Inputs!$C$55 -> 213 | D16: mm

Sheet Comparison
A1: Hand Calculation vs Module (engine stairs-0.1.0)
A2: Tolerance: ±2% forces/deflections, ±1% capacities and code limits. Module values are pasted from analyzeStairs() output.
A4: # | B4: Quantity | C4: Unit | D4: Hand | E4: Module | F4: Δ % | G4: Tol % | H4: Status | I4: Module source
B5: Loads
A6: 1 | B6: Flight dead load on plan | C6: kPa | D6: =Loads!$C$13 -> 8.1146781 | E6: 8.1146781 | F6: =IF(ABS(D6)<0.000000001,0,(E6-D6)/ABS(D6)) -> 0 | G6: 0.02 | H6: =IF(ABS(F6)<=G6,"MATCH","FLAG") -> MATCH | I6: result.loads.flight.total
A7: 2 | B7: Landing dead load | C7: kPa | D7: =Loads!$C$14 -> 5.8 | E7: 5.8 | F7: =IF(ABS(D7)<0.000000001,0,(E7-D7)/ABS(D7)) -> 0 | G7: 0.02 | H7: =IF(ABS(F7)<=G7,"MATCH","FLAG") -> MATCH | I7: result.loads.landings[0].dead
A8: 3 | B8: Pitch angle θ | C8: deg | D8: =Loads!$C$6 -> 24.346214 | E8: 24.346214 | F8: =IF(ABS(D8)<0.000000001,0,(E8-D8)/ABS(D8)) -> 0 | G8: 0.01 | H8: =IF(ABS(F8)<=G8,"MATCH","FLAG") -> MATCH | I8: result.pitch.degrees
B9: Flight 1 strip
A10: 4 | B10: Footing dead reaction | C10: kN/m | D10: =Frame!$C$17 -> 51.241684 | E10: 51.240847 | F10: =IF(ABS(D10)<0.000000001,0,(E10-D10)/ABS(D10)) -> -1.6325495e-05 | G10: 0.02 | H10: =IF(ABS(F10)<=G10,"MATCH","FLAG") -> MATCH | I10: strips[0].reactions[0].dead.v
A11: 5 | B11: Footing live reaction | C11: kN/m | D11: =Frame!$C$18 -> 31.580887 | E11: 31.580912 | F11: =IF(ABS(D11)<0.000000001,0,(E11-D11)/ABS(D11)) -> 8.0340304e-07 | G11: 0.02 | H11: =IF(ABS(F11)<=G11,"MATCH","FLAG") -> MATCH | I11: strips[0].reactions[0].live.v
A12: 6 | B12: Footing service thrust H | C12: kN/m | D12: =Frame!$C$19 -> 130.91948 | E12: 130.91779 | F12: =IF(ABS(D12)<0.000000001,0,(E12-D12)/ABS(D12)) -> -1.292098e-05 | G12: 0.02 | H12: =IF(ABS(F12)<=G12,"MATCH","FLAG") -> MATCH | I12: strips[0].reactions[0].service.h
A13: 7 | B13: Footing factored V max | C13: kN/m | D13: =Frame!$C$20 -> 112.01944 | E13: 112.01848 | F13: =IF(ABS(D13)<0.000000001,0,(E13-D13)/ABS(D13)) -> -8.5990393e-06 | G13: 0.02 | H13: =IF(ABS(F13)<=G13,"MATCH","FLAG") -> MATCH | I13: factored.vMax
A14: 8 | B14: Footing factored |H| max | C14: kN/m | D14: =Frame!$C$21 -> 177.26464 | E14: 177.26264 | F14: =IF(ABS(D14)<0.000000001,0,(E14-D14)/ABS(D14)) -> -1.129359e-05 | G14: 0.02 | H14: =IF(ABS(F14)<=G14,"MATCH","FLAG") -> MATCH | I14: factored.hAbsMax
A15: 9 | B15: Landing beam dead reaction | C15: kN/m | D15: =Frame!$C$22 -> 19.544084 | E15: 19.543532 | F15: =IF(ABS(D15)<0.000000001,0,(E15-D15)/ABS(D15)) -> -2.8244575e-05 | G15: 0.02 | H15: =IF(ABS(F15)<=G15,"MATCH","FLAG") -> MATCH | I15: strips[0].reactions[1].dead.v
A16: 10 | B16: Landing beam live reaction | C16: kN/m | D16: =Frame!$C$23 -> 13.296 | E16: 13.296 | F16: =IF(ABS(D16)<0.000000001,0,(E16-D16)/ABS(D16)) -> 6.7904634e-11 | G16: 0.02 | H16: =IF(ABS(F16)<=G16,"MATCH","FLAG") -> MATCH | I16: strips[0].reactions[1].live.v
A17: 11 | B17: Landing beam factored V min (uplift) | C17: kN/m | D17: =Frame!$C$24 -> -19.580276 | E17: -19.580212 | F17: =IF(ABS(D17)<0.000000001,0,(E17-D17)/ABS(D17)) -> 3.2602356e-06 | G17: 0.02 | H17: =IF(ABS(F17)<=G17,"MATCH","FLAG") -> MATCH | I17: factored.vMin
A18: 12 | B18: Mu+ waist (Excel closed form, released case) | C18: kN·m/m | D18: =Frame!$C$13 -> 65.349811 | E18: 65.35 | F18: =IF(ABS(D18)<0.000000001,0,(E18-D18)/ABS(D18)) -> 2.8927106e-06 | G18: 0.02 | H18: =IF(ABS(F18)<=G18,"MATCH","FLAG") -> MATCH | I18: check s1:flight-1:flexure-pos
A19: 13 | B19: Mu+ waist (force method) | C19: kN·m/m | D19: =Frame!$C$25 -> 65.350464 | E19: 65.345934 | F19: =IF(ABS(D19)<0.000000001,0,(E19-D19)/ABS(D19)) -> -6.9314988e-05 | G19: 0.02 | H19: =IF(ABS(F19)<=G19,"MATCH","FLAG") -> MATCH | I19: max station mPos
A20: 14 | B20: Mu− knee | C20: kN·m/m | D20: =Frame!$C$27 -> -30.33291 | E20: -30.339355 | F20: =IF(ABS(D20)<0.000000001,0,(E20-D20)/ABS(D20)) -> -0.00021249399 | G20: 0.02 | H20: =IF(ABS(F20)<=G20,"MATCH","FLAG") -> MATCH | I20: min station mNeg
A21: 15 | B21: Vu max outside support zones | C21: kN/m | D21: =Frame!$C$28 -> 40.567536 | E21: 40.586257 | F21: =IF(ABS(D21)<0.000000001,0,(E21-D21)/ABS(D21)) -> 0.00046146875 | G21: 0.02 | H21: =IF(ABS(F21)<=G21,"MATCH","FLAG") -> MATCH | I21: max station vu, |x − xs| ≥ b/2 + d
B22: Flight 2 strip
A23: 16 | B23: Landing beam dead reaction | C23: kN/m | D23: =Frame!$C$32 -> 15.153923 | E23: 15.153691 | F23: =IF(ABS(D23)<0.000000001,0,(E23-D23)/ABS(D23)) -> -1.5288533e-05 | G23: 0.02 | H23: =IF(ABS(F23)<=G23,"MATCH","FLAG") -> MATCH | I23: strips[1].reactions[0].dead.v
A24: 17 | B24: Top beam dead reaction | C24: kN/m | D24: =Frame!$C$33 -> 45.427496 | E24: 45.427114 | F24: =IF(ABS(D24)<0.000000001,0,(E24-D24)/ABS(D24)) -> -8.4027724e-06 | G24: 0.02 | H24: =IF(ABS(F24)<=G24,"MATCH","FLAG") -> MATCH | I24: strips[1].reactions[1].dead.v
A25: 18 | B25: Top beam live reaction | C25: kN/m | D25: =Frame!$C$34 -> 27.882941 | E25: 27.882921 | F25: =IF(ABS(D25)<0.000000001,0,(E25-D25)/ABS(D25)) -> -7.465464e-07 | G25: 0.02 | H25: =IF(ABS(F25)<=G25,"MATCH","FLAG") -> MATCH | I25: strips[1].reactions[1].live.v
A26: 19 | B26: Top beam factored fixed-end |M| | C26: kN·m/m | D26: =Frame!$C$35 -> 73.56358 | E26: 73.609615 | F26: =IF(ABS(D26)<0.000000001,0,(E26-D26)/ABS(D26)) -> 0.00062578894 | G26: 0.02 | H26: =IF(ABS(F26)<=G26,"MATCH","FLAG") -> MATCH | I26: factored.mAbsMax
A27: 20 | B27: Mu+ landing (at knee) | C27: kN·m/m | D27: =Frame!$C$36 -> 35.987066 | E27: 35.99 | F27: =IF(ABS(D27)<0.000000001,0,(E27-D27)/ABS(D27)) -> 8.1531287e-05 | G27: 0.02 | H27: =IF(ABS(F27)<=G27,"MATCH","FLAG") -> MATCH | I27: check s2:mid-landing:flexure-pos
A28: 21 | B28: Mu+ waist | C28: kN·m/m | D28: =Frame!$C$37 -> 41.134934 | E28: 41.13 | F28: =IF(ABS(D28)<0.000000001,0,(E28-D28)/ABS(D28)) -> -0.00011993665 | G28: 0.02 | H28: =IF(ABS(F28)<=G28,"MATCH","FLAG") -> MATCH | I28: check s2:flight-2:flexure-pos
A29: 22 | B29: Mu− knee (landing side) | C29: kN·m/m | D29: =Frame!$C$38 -> -17.196311 | E29: -17.2 | F29: =IF(ABS(D29)<0.000000001,0,(E29-D29)/ABS(D29)) -> -0.00021453343 | G29: 0.02 | H29: =IF(ABS(F29)<=G29,"MATCH","FLAG") -> MATCH | I29: check s2:mid-landing:flexure-neg:topKnee
A30: 23 | B30: Vu max outside support zones | C30: kN/m | D30: =Frame!$C$39 -> 52.831277 | E30: 52.855873 | F30: =IF(ABS(D30)<0.000000001,0,(E30-D30)/ABS(D30)) -> 0.00046555655 | G30: 0.02 | H30: =IF(ABS(F30)<=G30,"MATCH","FLAG") -> MATCH | I30: max station vu
A31: 24 | B31: Max axial tension | C31: kN/m | D31: =Frame!$C$40 -> 155.46308 | E31: 155.47235 | F31: =IF(ABS(D31)<0.000000001,0,(E31-D31)/ABS(D31)) -> 5.964619e-05 | G31: 0.02 | H31: =IF(ABS(F31)<=G31,"MATCH","FLAG") -> MATCH | I31: max station nuTension
B32: Section capacities
A33: 25 | B33: φMn B1 Ø12 @ 150 | C33: kN·m/m | D33: =Sections!$C$12 -> 47.013486 | E33: 47.01 | F33: =IF(ABS(D33)<0.000000001,0,(E33-D33)/ABS(D33)) -> -7.4150688e-05 | G33: 0.01 | H33: =IF(ABS(F33)<=G33,"MATCH","FLAG") -> MATCH | I33: check detail
A34: 26 | B34: φMn T2 Ø12 @ 300 | C34: kN·m/m | D34: =Sections!$C$26 -> 23.973991 | E34: 23.97 | F34: =IF(ABS(D34)<0.000000001,0,(E34-D34)/ABS(D34)) -> -0.00016647265 | G34: 0.01 | H34: =IF(ABS(F34)<=G34,"MATCH","FLAG") -> MATCH | I34: check detail
A35: 27 | B35: φMn T3 Ø12 @ 200 | C35: kN·m/m | D35: =Sections!$C$33 -> 35.610551 | E35: 35.61 | F35: =IF(ABS(D35)<0.000000001,0,(E35-D35)/ABS(D35)) -> -1.5460061e-05 | G35: 0.01 | H35: =IF(ABS(F35)<=G35,"MATCH","FLAG") -> MATCH | I35: check detail
A36: 28 | B36: εt B1 | D36: =Sections!$C$10 -> 0.030346939 | E36: 0.0303 | F36: =IF(ABS(D36)<0.000000001,0,(E36-D36)/ABS(D36)) -> -0.0015467606 | G36: 0.01 | H36: =IF(ABS(F36)<=G36,"MATCH","FLAG") -> MATCH | I36: check detail (4 d.p.)
A37: 29 | B37: As,min | C37: mm²/m | D37: =Sections!$C$44 -> 400 | E37: 400 | F37: =IF(ABS(D37)<0.000000001,0,(E37-D37)/ABS(D37)) -> 0 | G37: 0.01 | H37: =IF(ABS(F37)<=G37,"MATCH","FLAG") -> MATCH | I37: bars:mainBottom:minimum
A38: 30 | B38: Crack-control spacing | C38: mm | D38: =Sections!$C$47 -> 304.34783 | E38: 304 | F38: =IF(ABS(D38)<0.000000001,0,(E38-D38)/ABS(D38)) -> -0.0011428571 | G38: 0.01 | H38: =IF(ABS(F38)<=G38,"MATCH","FLAG") -> MATCH | I38: bars:mainBottom:crack
A39: 31 | B39: ld Ø12 bottom | C39: mm | D39: =Sections!$C$50 -> 317.41851 | E39: 317 | F39: =IF(ABS(D39)<0.000000001,0,(E39-D39)/ABS(D39)) -> -0.0013184741 | G39: 0.01 | H39: =IF(ABS(F39)<=G39,"MATCH","FLAG") -> MATCH | I39: detail:knee-bottom
A40: 32 | B40: ld Ø12 top (ψt 1.3) | C40: mm | D40: =Sections!$C$51 -> 412.64406 | E40: 413 | F40: =IF(ABS(D40)<0.000000001,0,(E40-D40)/ABS(D40)) -> 0.0008625824 | G40: 0.01 | H40: =IF(ABS(F40)<=G40,"MATCH","FLAG") -> MATCH | I40: detail:top-anchorage
A41: 33 | B41: ldh Ø12 | C41: mm | D41: =Sections!$C$53 -> 245.7869 | E41: 245.7869 | F41: =IF(ABS(D41)<0.000000001,0,(E41-D41)/ABS(D41)) -> 0 | G41: 0.01 | H41: =IF(ABS(F41)<=G41,"MATCH","FLAG") -> MATCH | I41: footing.dowelRequired
...

Sheet Findings
A1: Findings From the Benchmark (for engineer review)
A3: # | B3: Type | C3: Finding | D3: Evidence | E3: Recommendation | F3: Your decision
A4: 1 | B4: Module issue | C4: One-way shear reports φVc = 0 (DCR ∞) at a station where the governing combination has a tiny hogging moment and no top bars exist (ρw = 0). | D4: s1:flight-1:shear: Vu 29.61 kN/m at x = 3.69 m, Mu− only −1.29 kN·m/m; s2:flight-2:shear same at x = 5.13 m. Real governing shear: flight 1 Vu 40.6 vs φVc 67.0 (T3) → 0.61; flight 2 Vu 52.8 at b/2 + d from the top beam vs φVc 41.6 (T2 Ø12 @ 300 with Nu tension 155 kN/m) → 1.27, a genuine shear failure that the ∞ result hides. | E4: Take ρw from the bars actually in tension at that station; where the hogging zone has no top bars, use the bottom bars when |Mu−| < Mcr (section uncracked in hogging), else keep the 'no top bars' flag in flexure only. Fix in v1.1.
A5: 2 | B5: Modelling decision | C5: Thrust envelope keeps the horizontal restraint at the FIRST support. For flight 1 that is the footing on soil, which then carries 131 kN/m service thrust: resultant outside the 600 mm footing, sliding FS 0.31. | D5: footing:bearing 'Resultant outside footing', footing:sliding DCR 4.77. Hand calc reproduces H = 130.92 kN/m exactly, so the arithmetic is right; the assumption is the issue. | E5: When the bottom support is on ground, release the horizontal restraint at the footing (soil cannot take thrust) and let the landing beam / floor diaphragm carry it; check the footing for vertical load and friction only.
A6: 3 | B6: Modelling consequence | C6: In the restrained case the landing beam (pinned) takes 131 kN/m horizontal thrust and −19.6 kN/m factored uplift. | D6: strips[0].reactions[1].factored.vMin = −19.58 (hand −19.58). | E6: Report the landing-beam thrust and uplift in the reactions table so the beam is designed for them (currently a warning only).
A7: 4 | B7: Design result (inputs) | C7: Default bars fail for this geometry: B1 Ø12 @ 150 (DCR 1.39), T2 Ø12 @ 300 at fixed top (3.07); h = 200 < hmin and long-term deflection 78 mm > ℓ/240. | D7: Matches hand calc; this is the design, not the software. | E7: Not a software issue. Benchmark keeps module default bars so all checks are exercised.
A8: 5 | B8: Code note | C8: fy = 414 MPa (Grade 60) falls in the fy < 420 row of Table 24.4.3.2 → ρmin 0.0020 and hmin factor 0.991. | D8: Literal reading of ACI 318-19 SI tables; same in hand calc. | E8: Keep. Optionally treat 414 as Grade 420 (US Grade 60) to get 0.0018; your call.
A9: 6 | B9: Convention | C9: Steps' self-weight is applied up to the last riser line; between the last riser and the knee the landing load is used (concrete there is ~370 mm deep). | D9: Effect ≈ 0.8 kN per metre strip (< 1% of span load). Hand calc uses the same textbook convention, so this benchmark does not test it. | E9: Accept (standard practice).
